[2025-10-08T19:37:02.039+0000] {taskinstance.py:1103} INFO - Dependencies all met for dep_context=non-requeueable deps ti=<TaskInstance: 04_api_to_postgres.save_data_to_postgres manual__2025-10-08T19:36:51.697755+00:00 [queued]>
[2025-10-08T19:37:02.065+0000] {taskinstance.py:1103} INFO - Dependencies all met for dep_context=requeueable deps ti=<TaskInstance: 04_api_to_postgres.save_data_to_postgres manual__2025-10-08T19:36:51.697755+00:00 [queued]>
[2025-10-08T19:37:02.068+0000] {taskinstance.py:1308} INFO - Starting attempt 1 of 2
[2025-10-08T19:37:02.107+0000] {taskinstance.py:1327} INFO - Executing <Task(PythonOperator): save_data_to_postgres> on 2025-10-08 19:36:51.697755+00:00
[2025-10-08T19:37:02.128+0000] {standard_task_runner.py:57} INFO - Started process 2564 to run task
[2025-10-08T19:37:02.139+0000] {standard_task_runner.py:84} INFO - Running: ['***', 'tasks', 'run', '04_api_to_postgres', 'save_data_to_postgres', 'manual__2025-10-08T19:36:51.697755+00:00', '--job-id', '15', '--raw', '--subdir', 'DAGS_FOLDER/04_example.py', '--cfg-path', '/tmp/tmp2b3pv5rb']
[2025-10-08T19:37:02.144+0000] {standard_task_runner.py:85} INFO - Job 15: Subtask save_data_to_postgres
[2025-10-08T19:37:02.303+0000] {task_command.py:410} INFO - Running <TaskInstance: 04_api_to_postgres.save_data_to_postgres manual__2025-10-08T19:36:51.697755+00:00 [running]> on host a4407e4abc2c
[2025-10-08T19:37:02.503+0000] {taskinstance.py:1547} INFO - Exporting env vars: AIRFLOW_CTX_DAG_EMAIL='bryan@gmail.com' AIRFLOW_CTX_DAG_OWNER='andrei' AIRFLOW_CTX_DAG_ID='04_api_to_postgres' AIRFLOW_CTX_TASK_ID='save_data_to_postgres' AIRFLOW_CTX_EXECUTION_DATE='2025-10-08T19:36:51.697755+00:00' AIRFLOW_CTX_TRY_NUMBER='1' AIRFLOW_CTX_DAG_RUN_ID='manual__2025-10-08T19:36:51.697755+00:00'
[2025-10-08T19:37:02.552+0000] {base.py:73} INFO - Using connection ID 'postgres_datapath' for task execution.
[2025-10-08T19:37:02.582+0000] {sql.py:375} INFO - Running statement: INSERT INTO users (name,username,email) VALUES ('Leanne Graham','Bret','Sincere@april.biz');, parameters: None
[2025-10-08T19:37:02.596+0000] {taskinstance.py:1824} ERROR - Task failed with exception
Traceback (most recent call last):
  File "/home/airflow/.local/lib/python3.7/site-packages/airflow/operators/python.py", line 181, in execute
    return_value = self.execute_callable()
  File "/home/airflow/.local/lib/python3.7/site-packages/airflow/operators/python.py", line 198, in execute_callable
    return self.python_callable(*self.op_args, **self.op_kwargs)
  File "/opt/airflow/dags/04_example.py", line 39, in save_to_postgres
    postgreshook.run(f"INSERT INTO users (name,username,email) VALUES ('{name}','{username}','{email}');")
  File "/home/airflow/.local/lib/python3.7/site-packages/airflow/providers/common/sql/hooks/sql.py", line 349, in run
    self._run_command(cur, sql_statement, parameters)
  File "/home/airflow/.local/lib/python3.7/site-packages/airflow/providers/common/sql/hooks/sql.py", line 380, in _run_command
    cur.execute(sql_statement)
psycopg2.errors.UndefinedTable: relation "users" does not exist
LINE 1: INSERT INTO users (name,username,email) VALUES ('Leanne Grah...
                    ^

[2025-10-08T19:37:02.641+0000] {taskinstance.py:1350} INFO - Marking task as UP_FOR_RETRY. dag_id=04_api_to_postgres, task_id=save_data_to_postgres, execution_date=20251008T193651, start_date=20251008T193702, end_date=20251008T193702
[2025-10-08T19:37:02.680+0000] {standard_task_runner.py:109} ERROR - Failed to execute job 15 for task save_data_to_postgres (relation "users" does not exist
LINE 1: INSERT INTO users (name,username,email) VALUES ('Leanne Grah...
                    ^
; 2564)
[2025-10-08T19:37:02.754+0000] {local_task_job_runner.py:225} INFO - Task exited with return code 1
[2025-10-08T19:37:02.794+0000] {taskinstance.py:2653} INFO - 0 downstream tasks scheduled from follow-on schedule check
