[2025-10-16T19:39:38.204+0000] {taskinstance.py:1103} INFO - Dependencies all met for dep_context=non-requeueable deps ti=<TaskInstance: 04_api_to_postgres.save_data_to_postgres 10 [queued]>
[2025-10-16T19:39:38.261+0000] {taskinstance.py:1103} INFO - Dependencies all met for dep_context=requeueable deps ti=<TaskInstance: 04_api_to_postgres.save_data_to_postgres 10 [queued]>
[2025-10-16T19:39:38.263+0000] {taskinstance.py:1308} INFO - Starting attempt 1 of 2
[2025-10-16T19:39:38.314+0000] {taskinstance.py:1327} INFO - Executing <Task(PythonOperator): save_data_to_postgres> on 2025-10-16 19:39:20+00:00
[2025-10-16T19:39:38.345+0000] {standard_task_runner.py:57} INFO - Started process 332 to run task
[2025-10-16T19:39:38.361+0000] {standard_task_runner.py:84} INFO - Running: ['***', 'tasks', 'run', '04_api_to_postgres', 'save_data_to_postgres', '10', '--job-id', '6', '--raw', '--subdir', 'DAGS_FOLDER/04_example.py', '--cfg-path', '/tmp/tmptgd_77r_']
[2025-10-16T19:39:38.368+0000] {standard_task_runner.py:85} INFO - Job 6: Subtask save_data_to_postgres
[2025-10-16T19:39:38.604+0000] {task_command.py:410} INFO - Running <TaskInstance: 04_api_to_postgres.save_data_to_postgres 10 [running]> on host 2cdd767518d4
[2025-10-16T19:39:38.929+0000] {taskinstance.py:1547} INFO - Exporting env vars: AIRFLOW_CTX_DAG_EMAIL='bryan@gmail.com' AIRFLOW_CTX_DAG_OWNER='andrei' AIRFLOW_CTX_DAG_ID='04_api_to_postgres' AIRFLOW_CTX_TASK_ID='save_data_to_postgres' AIRFLOW_CTX_EXECUTION_DATE='2025-10-16T19:39:20+00:00' AIRFLOW_CTX_TRY_NUMBER='1' AIRFLOW_CTX_DAG_RUN_ID='10'
[2025-10-16T19:39:39.032+0000] {taskinstance.py:1824} ERROR - Task failed with exception
Traceback (most recent call last):
  File "/home/airflow/.local/lib/python3.7/site-packages/airflow/operators/python.py", line 181, in execute
    return_value = self.execute_callable()
  File "/home/airflow/.local/lib/python3.7/site-packages/airflow/operators/python.py", line 198, in execute_callable
    return self.python_callable(*self.op_args, **self.op_kwargs)
  File "/opt/airflow/dags/04_example.py", line 39, in save_to_postgres
    postgreshook.run(f"INSERT INTO users (name,username,email) VALUES ('{name}','{username}','{email}');")
  File "/home/airflow/.local/lib/python3.7/site-packages/airflow/providers/common/sql/hooks/sql.py", line 342, in run
    with closing(self.get_conn()) as conn:
  File "/home/airflow/.local/lib/python3.7/site-packages/airflow/providers/postgres/hooks/postgres.py", line 118, in get_conn
    conn = deepcopy(self.connection or self.get_connection(conn_id))
  File "/home/airflow/.local/lib/python3.7/site-packages/airflow/hooks/base.py", line 72, in get_connection
    conn = Connection.get_connection_from_secrets(conn_id)
  File "/home/airflow/.local/lib/python3.7/site-packages/airflow/models/connection.py", line 434, in get_connection_from_secrets
    raise AirflowNotFoundException(f"The conn_id `{conn_id}` isn't defined")
airflow.exceptions.AirflowNotFoundException: The conn_id `postgres_datapath` isn't defined
[2025-10-16T19:39:39.056+0000] {taskinstance.py:1350} INFO - Marking task as UP_FOR_RETRY. dag_id=04_api_to_postgres, task_id=save_data_to_postgres, execution_date=20251016T193920, start_date=20251016T193938, end_date=20251016T193939
[2025-10-16T19:39:39.092+0000] {standard_task_runner.py:109} ERROR - Failed to execute job 6 for task save_data_to_postgres (The conn_id `postgres_datapath` isn't defined; 332)
[2025-10-16T19:39:39.175+0000] {local_task_job_runner.py:225} INFO - Task exited with return code 1
[2025-10-16T19:39:39.250+0000] {taskinstance.py:2653} INFO - 0 downstream tasks scheduled from follow-on schedule check
